INFO:     Started server process [58583]
INFO:     Waiting for application startup.
Failed to initialize Local LLM: Local LLM connection failed: Cannot connect to host 127.0.0.1:1234 ssl:default [Connect call failed ('127.0.0.1', 1234)]
Failed to initialize Local LLM: Local LLM connection failed: Cannot connect to host 127.0.0.1:1234 ssl:default [Connect call failed ('127.0.0.1', 1234)]
Failed to load conversation history: 'VectorStore' object has no attribute 'get_conversation_history'
INFO:     Application startup complete.
INFO:     Uvicorn running on http://0.0.0.0:8000 (Press CTRL+C to quit)
INFO:     127.0.0.1:41732 - "GET /health HTTP/1.1" 200 OK
INFO:     127.0.0.1:40878 - "GET /health HTTP/1.1" 200 OK
ERROR:root:Failed to get system info: 'DatabaseConfig' object has no attribute 'sqlite_path'
Traceback (most recent call last):
  File "/workspace/src/api/server.py", line 526, in get_system_info
    "path": cfg.database.sqlite_path
            ^^^^^^^^^^^^^^^^^^^^^^^^
  File "/workspace/venv/lib/python3.13/site-packages/pydantic/main.py", line 991, in __getattr__
    raise AttributeError(f'{type(self).__name__!r} object has no attribute {item!r}')
AttributeError: 'DatabaseConfig' object has no attribute 'sqlite_path'
INFO:     127.0.0.1:40878 - "GET /system/info HTTP/1.1" 200 OK
INFO:     127.0.0.1:40878 - "POST /workflows HTTP/1.1" 200 OK
ERROR:src.core.orchestrator:Workflow execution failed: 'DatabaseManager' object has no attribute 'update_workflow_status'
Traceback (most recent call last):
  File "/workspace/src/core/orchestrator.py", line 192, in _execute_workflow_async
    await self._update_workflow_status(workflow_id, WorkflowStatus.PLANNING)
  File "/workspace/src/core/orchestrator.py", line 411, in _update_workflow_status
    await self.database.update_workflow_status(workflow_id, status)
          ^^^^^^^^^^^^^^^^^^^^^^^^^^^^^^^^^^^^
AttributeError: 'DatabaseManager' object has no attribute 'update_workflow_status'
ERROR:asyncio:Task exception was never retrieved
future: <Task finished name='Task-13' coro=<MultiAgentOrchestrator._execute_workflow_async() done, defined at /workspace/src/core/orchestrator.py:188> exception=AttributeError("'DatabaseManager' object has no attribute 'update_workflow_status'")>
Traceback (most recent call last):
  File "/workspace/src/core/orchestrator.py", line 192, in _execute_workflow_async
    await self._update_workflow_status(workflow_id, WorkflowStatus.PLANNING)
  File "/workspace/src/core/orchestrator.py", line 411, in _update_workflow_status
    await self.database.update_workflow_status(workflow_id, status)
          ^^^^^^^^^^^^^^^^^^^^^^^^^^^^^^^^^^^^
AttributeError: 'DatabaseManager' object has no attribute 'update_workflow_status'

During handling of the above exception, another exception occurred:

Traceback (most recent call last):
  File "/workspace/src/core/orchestrator.py", line 208, in _execute_workflow_async
    await self._update_workflow_status(workflow_id, WorkflowStatus.FAILED)
  File "/workspace/src/core/orchestrator.py", line 411, in _update_workflow_status
    await self.database.update_workflow_status(workflow_id, status)
          ^^^^^^^^^^^^^^^^^^^^^^^^^^^^^^^^^^^^
AttributeError: 'DatabaseManager' object has no attribute 'update_workflow_status'
INFO:     127.0.0.1:40878 - "GET /workflows/4527d6cd-c469-4c31-9606-f79c1b65be25 HTTP/1.1" 200 OK
WARNING:src.core.ai_provider:All AI providers failed, using fallback response
ERROR:src.agents.conversational:Chat failed: VectorStore.store_conversation() missing 1 required positional argument: 'conversation_data'
Traceback (most recent call last):
  File "/workspace/src/agents/conversational.py", line 172, in chat
    await self.vector_store.store_conversation(conversation)
          ~~~~~~~~~~~~~~~~~~~~~~~~~~~~~~~~~~~~^^^^^^^^^^^^^^
TypeError: VectorStore.store_conversation() missing 1 required positional argument: 'conversation_data'
INFO:     127.0.0.1:40878 - "POST /chat HTTP/1.1" 200 OK
WARNING:src.agents.search:Google Search API not configured
WARNING:src.agents.search:Bing Search API not configured
WARNING:src.agents.search:GitHub token not configured
INFO:     127.0.0.1:40878 - "POST /search HTTP/1.1" 200 OK
WARNING:root:Agent execution failed, using fallback: 'ExecutionAgent' object has no attribute 'execute_automation'
INFO:     127.0.0.1:40878 - "POST /automation/execute HTTP/1.1" 200 OK
INFO:     127.0.0.1:40878 - "POST /export HTTP/1.1" 200 OK
ERROR:root:Failed to get system info: 'DatabaseConfig' object has no attribute 'sqlite_path'
Traceback (most recent call last):
  File "/workspace/src/api/server.py", line 526, in get_system_info
    "path": cfg.database.sqlite_path
            ^^^^^^^^^^^^^^^^^^^^^^^^
  File "/workspace/venv/lib/python3.13/site-packages/pydantic/main.py", line 991, in __getattr__
    raise AttributeError(f'{type(self).__name__!r} object has no attribute {item!r}')
AttributeError: 'DatabaseConfig' object has no attribute 'sqlite_path'
INFO:     127.0.0.1:40878 - "GET /system/info HTTP/1.1" 200 OK
ERROR:root:Failed to get system info: 'DatabaseConfig' object has no attribute 'sqlite_path'
Traceback (most recent call last):
  File "/workspace/src/api/server.py", line 526, in get_system_info
    "path": cfg.database.sqlite_path
            ^^^^^^^^^^^^^^^^^^^^^^^^
  File "/workspace/venv/lib/python3.13/site-packages/pydantic/main.py", line 991, in __getattr__
    raise AttributeError(f'{type(self).__name__!r} object has no attribute {item!r}')
AttributeError: 'DatabaseConfig' object has no attribute 'sqlite_path'
INFO:     127.0.0.1:40878 - "GET /system/info HTTP/1.1" 200 OK
