INFO:     Started server process [201671]
INFO:     Waiting for application startup.
Failed to initialize Local LLM: Local LLM connection failed: Cannot connect to host 127.0.0.1:1234 ssl:default [Connect call failed ('127.0.0.1', 1234)]
Failed to initialize Local LLM: Local LLM connection failed: Cannot connect to host 127.0.0.1:1234 ssl:default [Connect call failed ('127.0.0.1', 1234)]
INFO:     Application startup complete.
INFO:     Uvicorn running on http://0.0.0.0:8000 (Press CTRL+C to quit)
WARNING:src.core.ai_provider:All AI providers failed, using fallback response
INFO:     127.0.0.1:54950 - "POST /chat HTTP/1.1" 200 OK
WARNING:src.core.ai_provider:All AI providers failed, using fallback response
INFO:     127.0.0.1:54960 - "POST /chat HTTP/1.1" 200 OK
WARNING:src.core.ai_provider:All AI providers failed, using fallback response
INFO:     127.0.0.1:54968 - "POST /chat HTTP/1.1" 200 OK
WARNING:src.core.ai_provider:All AI providers failed, using fallback response
INFO:     127.0.0.1:35176 - "POST /chat HTTP/1.1" 200 OK
WARNING:src.utils.media_capture:Media libraries not available, using basic capture
WARNING:src.utils.media_capture:Media libraries not available, using basic capture
WARNING:src.utils.media_capture:Media libraries not available, using basic capture
WARNING:src.utils.media_capture:Media libraries not available, using basic capture
WARNING:src.utils.media_capture:Media libraries not available, using basic capture
WARNING:src.utils.media_capture:Media libraries not available, using basic capture
WARNING:src.utils.media_capture:Media libraries not available, using basic capture
INFO:     127.0.0.1:34528 - "POST /automation/execute HTTP/1.1" 200 OK
WARNING:src.agents.search:Failed to parse JSON response: 200, message='Attempt to decode JSON with unexpected mimetype: application/x-javascript', url='https://api.duckduckgo.com/?q=latest+AI+automation+trends+2024&format=json&no_html=1&skip_disambig=1'
INFO:     127.0.0.1:39678 - "POST /search HTTP/1.1" 200 OK
WARNING:src.core.ai_provider:All AI providers failed, using fallback response
INFO:     127.0.0.1:39090 - "POST /chat HTTP/1.1" 200 OK
WARNING:src.core.ai_provider:All AI providers failed, using fallback response
INFO:     127.0.0.1:39094 - "POST /chat HTTP/1.1" 200 OK
WARNING:src.core.ai_provider:All AI providers failed, using fallback response
INFO:     127.0.0.1:44720 - "POST /chat HTTP/1.1" 200 OK
WARNING:src.core.ai_provider:All AI providers failed, using fallback response
INFO:     127.0.0.1:44722 - "POST /chat HTTP/1.1" 200 OK
ERROR:root:Export failed: No module named 'openpyxl'
Traceback (most recent call last):
  File "/workspace/src/api/server.py", line 450, in export_data
    df.to_excel(excel_path, index=False, engine='openpyxl')
    ~~~~~~~~~~~^^^^^^^^^^^^^^^^^^^^^^^^^^^^^^^^^^^^^^^^^^^^
  File "/workspace/venv/lib/python3.13/site-packages/pandas/util/_decorators.py", line 333, in wrapper
    return func(*args, **kwargs)
  File "/workspace/venv/lib/python3.13/site-packages/pandas/core/generic.py", line 2436, in to_excel
    formatter.write(
    ~~~~~~~~~~~~~~~^
        excel_writer,
        ^^^^^^^^^^^^^
    ...<6 lines>...
        engine_kwargs=engine_kwargs,
        ^^^^^^^^^^^^^^^^^^^^^^^^^^^^
    )
    ^
  File "/workspace/venv/lib/python3.13/site-packages/pandas/io/formats/excel.py", line 943, in write
    writer = ExcelWriter(
        writer,
    ...<2 lines>...
        engine_kwargs=engine_kwargs,
    )
  File "/workspace/venv/lib/python3.13/site-packages/pandas/io/excel/_openpyxl.py", line 57, in __init__
    from openpyxl.workbook import Workbook
ModuleNotFoundError: No module named 'openpyxl'
INFO:     127.0.0.1:42246 - "POST /export HTTP/1.1" 200 OK
INFO:     127.0.0.1:42256 - "POST /export HTTP/1.1" 200 OK
INFO:     127.0.0.1:33420 - "POST /workflows HTTP/1.1" 200 OK
ERROR:src.core.orchestrator:Workflow execution failed: 'DatabaseManager' object has no attribute 'update_workflow_status'
Traceback (most recent call last):
  File "/workspace/src/core/orchestrator.py", line 197, in _execute_workflow_async
    await self._update_workflow_status(workflow_id, WorkflowStatus.PLANNING)
  File "/workspace/src/core/orchestrator.py", line 416, in _update_workflow_status
    await self.database.update_workflow_status(workflow_id, status)
          ^^^^^^^^^^^^^^^^^^^^^^^^^^^^^^^^^^^^
AttributeError: 'DatabaseManager' object has no attribute 'update_workflow_status'
ERROR:asyncio:Task exception was never retrieved
future: <Task finished name='Task-29' coro=<MultiAgentOrchestrator._execute_workflow_async() done, defined at /workspace/src/core/orchestrator.py:193> exception=AttributeError("'DatabaseManager' object has no attribute 'update_workflow_status'")>
Traceback (most recent call last):
  File "/workspace/src/core/orchestrator.py", line 197, in _execute_workflow_async
    await self._update_workflow_status(workflow_id, WorkflowStatus.PLANNING)
  File "/workspace/src/core/orchestrator.py", line 416, in _update_workflow_status
    await self.database.update_workflow_status(workflow_id, status)
          ^^^^^^^^^^^^^^^^^^^^^^^^^^^^^^^^^^^^
AttributeError: 'DatabaseManager' object has no attribute 'update_workflow_status'

During handling of the above exception, another exception occurred:

Traceback (most recent call last):
  File "/workspace/src/core/orchestrator.py", line 213, in _execute_workflow_async
    await self._update_workflow_status(workflow_id, WorkflowStatus.FAILED)
  File "/workspace/src/core/orchestrator.py", line 416, in _update_workflow_status
    await self.database.update_workflow_status(workflow_id, status)
          ^^^^^^^^^^^^^^^^^^^^^^^^^^^^^^^^^^^^
AttributeError: 'DatabaseManager' object has no attribute 'update_workflow_status'
INFO:     127.0.0.1:33426 - "GET /health HTTP/1.1" 200 OK
INFO:     127.0.0.1:37076 - "GET /health HTTP/1.1" 200 OK
