INFO:     Started server process [58583]
INFO:     Waiting for application startup.
Failed to initialize Local LLM: Local LLM connection failed: Cannot connect to host 127.0.0.1:1234 ssl:default [Connect call failed ('127.0.0.1', 1234)]
Failed to initialize Local LLM: Local LLM connection failed: Cannot connect to host 127.0.0.1:1234 ssl:default [Connect call failed ('127.0.0.1', 1234)]
Failed to load conversation history: 'VectorStore' object has no attribute 'get_conversation_history'
INFO:     Application startup complete.
INFO:     Uvicorn running on http://0.0.0.0:8000 (Press CTRL+C to quit)
INFO:     127.0.0.1:41732 - "GET /health HTTP/1.1" 200 OK
INFO:     127.0.0.1:40878 - "GET /health HTTP/1.1" 200 OK
ERROR:root:Failed to get system info: 'DatabaseConfig' object has no attribute 'sqlite_path'
Traceback (most recent call last):
  File "/workspace/src/api/server.py", line 526, in get_system_info
    "path": cfg.database.sqlite_path
            ^^^^^^^^^^^^^^^^^^^^^^^^
  File "/workspace/venv/lib/python3.13/site-packages/pydantic/main.py", line 991, in __getattr__
    raise AttributeError(f'{type(self).__name__!r} object has no attribute {item!r}')
AttributeError: 'DatabaseConfig' object has no attribute 'sqlite_path'
INFO:     127.0.0.1:40878 - "GET /system/info HTTP/1.1" 200 OK
INFO:     127.0.0.1:40878 - "POST /workflows HTTP/1.1" 200 OK
ERROR:src.core.orchestrator:Workflow execution failed: 'DatabaseManager' object has no attribute 'update_workflow_status'
Traceback (most recent call last):
  File "/workspace/src/core/orchestrator.py", line 192, in _execute_workflow_async
    await self._update_workflow_status(workflow_id, WorkflowStatus.PLANNING)
  File "/workspace/src/core/orchestrator.py", line 411, in _update_workflow_status
    await self.database.update_workflow_status(workflow_id, status)
          ^^^^^^^^^^^^^^^^^^^^^^^^^^^^^^^^^^^^
AttributeError: 'DatabaseManager' object has no attribute 'update_workflow_status'
ERROR:asyncio:Task exception was never retrieved
future: <Task finished name='Task-13' coro=<MultiAgentOrchestrator._execute_workflow_async() done, defined at /workspace/src/core/orchestrator.py:188> exception=AttributeError("'DatabaseManager' object has no attribute 'update_workflow_status'")>
Traceback (most recent call last):
  File "/workspace/src/core/orchestrator.py", line 192, in _execute_workflow_async
    await self._update_workflow_status(workflow_id, WorkflowStatus.PLANNING)
  File "/workspace/src/core/orchestrator.py", line 411, in _update_workflow_status
    await self.database.update_workflow_status(workflow_id, status)
          ^^^^^^^^^^^^^^^^^^^^^^^^^^^^^^^^^^^^
AttributeError: 'DatabaseManager' object has no attribute 'update_workflow_status'

During handling of the above exception, another exception occurred:

Traceback (most recent call last):
  File "/workspace/src/core/orchestrator.py", line 208, in _execute_workflow_async
    await self._update_workflow_status(workflow_id, WorkflowStatus.FAILED)
  File "/workspace/src/core/orchestrator.py", line 411, in _update_workflow_status
    await self.database.update_workflow_status(workflow_id, status)
          ^^^^^^^^^^^^^^^^^^^^^^^^^^^^^^^^^^^^
AttributeError: 'DatabaseManager' object has no attribute 'update_workflow_status'
INFO:     127.0.0.1:40878 - "GET /workflows/4527d6cd-c469-4c31-9606-f79c1b65be25 HTTP/1.1" 200 OK
WARNING:src.core.ai_provider:All AI providers failed, using fallback response
ERROR:src.agents.conversational:Chat failed: VectorStore.store_conversation() missing 1 required positional argument: 'conversation_data'
Traceback (most recent call last):
  File "/workspace/src/agents/conversational.py", line 172, in chat
    await self.vector_store.store_conversation(conversation)
          ~~~~~~~~~~~~~~~~~~~~~~~~~~~~~~~~~~~~^^^^^^^^^^^^^^
TypeError: VectorStore.store_conversation() missing 1 required positional argument: 'conversation_data'
INFO:     127.0.0.1:40878 - "POST /chat HTTP/1.1" 200 OK
WARNING:src.agents.search:Google Search API not configured
WARNING:src.agents.search:Bing Search API not configured
WARNING:src.agents.search:GitHub token not configured
INFO:     127.0.0.1:40878 - "POST /search HTTP/1.1" 200 OK
WARNING:root:Agent execution failed, using fallback: 'ExecutionAgent' object has no attribute 'execute_automation'
INFO:     127.0.0.1:40878 - "POST /automation/execute HTTP/1.1" 200 OK
INFO:     127.0.0.1:40878 - "POST /export HTTP/1.1" 200 OK
ERROR:root:Failed to get system info: 'DatabaseConfig' object has no attribute 'sqlite_path'
Traceback (most recent call last):
  File "/workspace/src/api/server.py", line 526, in get_system_info
    "path": cfg.database.sqlite_path
            ^^^^^^^^^^^^^^^^^^^^^^^^
  File "/workspace/venv/lib/python3.13/site-packages/pydantic/main.py", line 991, in __getattr__
    raise AttributeError(f'{type(self).__name__!r} object has no attribute {item!r}')
AttributeError: 'DatabaseConfig' object has no attribute 'sqlite_path'
INFO:     127.0.0.1:40878 - "GET /system/info HTTP/1.1" 200 OK
ERROR:root:Failed to get system info: 'DatabaseConfig' object has no attribute 'sqlite_path'
Traceback (most recent call last):
  File "/workspace/src/api/server.py", line 526, in get_system_info
    "path": cfg.database.sqlite_path
            ^^^^^^^^^^^^^^^^^^^^^^^^
  File "/workspace/venv/lib/python3.13/site-packages/pydantic/main.py", line 991, in __getattr__
    raise AttributeError(f'{type(self).__name__!r} object has no attribute {item!r}')
AttributeError: 'DatabaseConfig' object has no attribute 'sqlite_path'
INFO:     127.0.0.1:40878 - "GET /system/info HTTP/1.1" 200 OK
INFO:     127.0.0.1:45538 - "GET /health HTTP/1.1" 200 OK
ERROR:root:Failed to get system info: 'DatabaseConfig' object has no attribute 'sqlite_path'
Traceback (most recent call last):
  File "/workspace/src/api/server.py", line 526, in get_system_info
    "path": cfg.database.sqlite_path
            ^^^^^^^^^^^^^^^^^^^^^^^^
  File "/workspace/venv/lib/python3.13/site-packages/pydantic/main.py", line 991, in __getattr__
    raise AttributeError(f'{type(self).__name__!r} object has no attribute {item!r}')
AttributeError: 'DatabaseConfig' object has no attribute 'sqlite_path'
INFO:     127.0.0.1:45538 - "GET /system/info HTTP/1.1" 200 OK
INFO:     127.0.0.1:45538 - "POST /workflows HTTP/1.1" 200 OK
ERROR:src.core.orchestrator:Workflow execution failed: 'DatabaseManager' object has no attribute 'update_workflow_status'
Traceback (most recent call last):
  File "/workspace/src/core/orchestrator.py", line 192, in _execute_workflow_async
    await self._update_workflow_status(workflow_id, WorkflowStatus.PLANNING)
  File "/workspace/src/core/orchestrator.py", line 411, in _update_workflow_status
    await self.database.update_workflow_status(workflow_id, status)
          ^^^^^^^^^^^^^^^^^^^^^^^^^^^^^^^^^^^^
AttributeError: 'DatabaseManager' object has no attribute 'update_workflow_status'
ERROR:asyncio:Task exception was never retrieved
future: <Task finished name='Task-24' coro=<MultiAgentOrchestrator._execute_workflow_async() done, defined at /workspace/src/core/orchestrator.py:188> exception=AttributeError("'DatabaseManager' object has no attribute 'update_workflow_status'")>
Traceback (most recent call last):
  File "/workspace/src/core/orchestrator.py", line 192, in _execute_workflow_async
    await self._update_workflow_status(workflow_id, WorkflowStatus.PLANNING)
  File "/workspace/src/core/orchestrator.py", line 411, in _update_workflow_status
    await self.database.update_workflow_status(workflow_id, status)
          ^^^^^^^^^^^^^^^^^^^^^^^^^^^^^^^^^^^^
AttributeError: 'DatabaseManager' object has no attribute 'update_workflow_status'

During handling of the above exception, another exception occurred:

Traceback (most recent call last):
  File "/workspace/src/core/orchestrator.py", line 208, in _execute_workflow_async
    await self._update_workflow_status(workflow_id, WorkflowStatus.FAILED)
  File "/workspace/src/core/orchestrator.py", line 411, in _update_workflow_status
    await self.database.update_workflow_status(workflow_id, status)
          ^^^^^^^^^^^^^^^^^^^^^^^^^^^^^^^^^^^^
AttributeError: 'DatabaseManager' object has no attribute 'update_workflow_status'
INFO:     127.0.0.1:45538 - "GET /workflows/0ba49a2c-bb5f-4228-a79f-57f0d6becfc2 HTTP/1.1" 200 OK
WARNING:src.core.ai_provider:All AI providers failed, using fallback response
ERROR:src.agents.conversational:Chat failed: VectorStore.store_conversation() missing 1 required positional argument: 'conversation_data'
Traceback (most recent call last):
  File "/workspace/src/agents/conversational.py", line 172, in chat
    await self.vector_store.store_conversation(conversation)
          ~~~~~~~~~~~~~~~~~~~~~~~~~~~~~~~~~~~~^^^^^^^^^^^^^^
TypeError: VectorStore.store_conversation() missing 1 required positional argument: 'conversation_data'
INFO:     127.0.0.1:45538 - "POST /chat HTTP/1.1" 200 OK
WARNING:src.agents.search:Google Search API not configured
WARNING:src.agents.search:Bing Search API not configured
WARNING:src.agents.search:GitHub token not configured
INFO:     127.0.0.1:45538 - "POST /search HTTP/1.1" 200 OK
WARNING:root:Agent execution failed, using fallback: 'ExecutionAgent' object has no attribute 'execute_automation'
INFO:     127.0.0.1:45538 - "POST /automation/execute HTTP/1.1" 200 OK
INFO:     127.0.0.1:45538 - "POST /export HTTP/1.1" 200 OK
ERROR:root:Failed to get system info: 'DatabaseConfig' object has no attribute 'sqlite_path'
Traceback (most recent call last):
  File "/workspace/src/api/server.py", line 526, in get_system_info
    "path": cfg.database.sqlite_path
            ^^^^^^^^^^^^^^^^^^^^^^^^
  File "/workspace/venv/lib/python3.13/site-packages/pydantic/main.py", line 991, in __getattr__
    raise AttributeError(f'{type(self).__name__!r} object has no attribute {item!r}')
AttributeError: 'DatabaseConfig' object has no attribute 'sqlite_path'
INFO:     127.0.0.1:45538 - "GET /system/info HTTP/1.1" 200 OK
ERROR:root:Failed to get system info: 'DatabaseConfig' object has no attribute 'sqlite_path'
Traceback (most recent call last):
  File "/workspace/src/api/server.py", line 526, in get_system_info
    "path": cfg.database.sqlite_path
            ^^^^^^^^^^^^^^^^^^^^^^^^
  File "/workspace/venv/lib/python3.13/site-packages/pydantic/main.py", line 991, in __getattr__
    raise AttributeError(f'{type(self).__name__!r} object has no attribute {item!r}')
AttributeError: 'DatabaseConfig' object has no attribute 'sqlite_path'
INFO:     127.0.0.1:45538 - "GET /system/info HTTP/1.1" 200 OK
WARNING:src.core.ai_provider:All AI providers failed, using fallback response
ERROR:src.agents.conversational:Chat failed: VectorStore.store_conversation() missing 1 required positional argument: 'conversation_data'
Traceback (most recent call last):
  File "/workspace/src/agents/conversational.py", line 172, in chat
    await self.vector_store.store_conversation(conversation)
          ~~~~~~~~~~~~~~~~~~~~~~~~~~~~~~~~~~~~^^^^^^^^^^^^^^
TypeError: VectorStore.store_conversation() missing 1 required positional argument: 'conversation_data'
INFO:     127.0.0.1:40244 - "POST /chat HTTP/1.1" 200 OK
INFO:     127.0.0.1:50962 - "POST /workflows HTTP/1.1" 200 OK
ERROR:src.core.orchestrator:Workflow execution failed: 'DatabaseManager' object has no attribute 'update_workflow_status'
Traceback (most recent call last):
  File "/workspace/src/core/orchestrator.py", line 192, in _execute_workflow_async
    await self._update_workflow_status(workflow_id, WorkflowStatus.PLANNING)
  File "/workspace/src/core/orchestrator.py", line 411, in _update_workflow_status
    await self.database.update_workflow_status(workflow_id, status)
          ^^^^^^^^^^^^^^^^^^^^^^^^^^^^^^^^^^^^
AttributeError: 'DatabaseManager' object has no attribute 'update_workflow_status'
ERROR:asyncio:Task exception was never retrieved
future: <Task finished name='Task-34' coro=<MultiAgentOrchestrator._execute_workflow_async() done, defined at /workspace/src/core/orchestrator.py:188> exception=AttributeError("'DatabaseManager' object has no attribute 'update_workflow_status'")>
Traceback (most recent call last):
  File "/workspace/src/core/orchestrator.py", line 192, in _execute_workflow_async
    await self._update_workflow_status(workflow_id, WorkflowStatus.PLANNING)
  File "/workspace/src/core/orchestrator.py", line 411, in _update_workflow_status
    await self.database.update_workflow_status(workflow_id, status)
          ^^^^^^^^^^^^^^^^^^^^^^^^^^^^^^^^^^^^
AttributeError: 'DatabaseManager' object has no attribute 'update_workflow_status'

During handling of the above exception, another exception occurred:

Traceback (most recent call last):
  File "/workspace/src/core/orchestrator.py", line 208, in _execute_workflow_async
    await self._update_workflow_status(workflow_id, WorkflowStatus.FAILED)
  File "/workspace/src/core/orchestrator.py", line 411, in _update_workflow_status
    await self.database.update_workflow_status(workflow_id, status)
          ^^^^^^^^^^^^^^^^^^^^^^^^^^^^^^^^^^^^
AttributeError: 'DatabaseManager' object has no attribute 'update_workflow_status'
INFO:     127.0.0.1:50966 - "GET /workflows/6236015b-0dcb-426d-884e-6aee6cc8b0bd HTTP/1.1" 200 OK
WARNING:root:Agent execution failed, using fallback: 'ExecutionAgent' object has no attribute 'execute_automation'
INFO:     127.0.0.1:41354 - "POST /automation/execute HTTP/1.1" 200 OK
ERROR:src.agents.search:DuckDuckGo search error: 200, message='Attempt to decode JSON with unexpected mimetype: application/x-javascript', url='https://api.duckduckgo.com/?q=automation+best+practices&format=json&no_html=1&skip_disambig=1'
INFO:     127.0.0.1:53948 - "POST /search HTTP/1.1" 200 OK
INFO:     127.0.0.1:50612 - "POST /export HTTP/1.1" 200 OK
WARNING:root:Agent execution failed, using fallback: 'ExecutionAgent' object has no attribute 'execute_automation'
INFO:     127.0.0.1:32876 - "POST /automation/execute HTTP/1.1" 200 OK
ERROR:src.agents.search:DuckDuckGo search error: 200, message='Attempt to decode JSON with unexpected mimetype: application/x-javascript', url='https://api.duckduckgo.com/?q=latest+AI+automation+trends+2024&format=json&no_html=1&skip_disambig=1'
WARNING:src.agents.search:Google Search API not configured
INFO:     127.0.0.1:32882 - "POST /search HTTP/1.1" 200 OK
WARNING:src.core.ai_provider:All AI providers failed, using fallback response
ERROR:src.agents.conversational:Chat failed: VectorStore.store_conversation() missing 1 required positional argument: 'conversation_data'
Traceback (most recent call last):
  File "/workspace/src/agents/conversational.py", line 172, in chat
    await self.vector_store.store_conversation(conversation)
          ~~~~~~~~~~~~~~~~~~~~~~~~~~~~~~~~~~~~^^^^^^^^^^^^^^
TypeError: VectorStore.store_conversation() missing 1 required positional argument: 'conversation_data'
INFO:     127.0.0.1:32894 - "POST /chat HTTP/1.1" 200 OK
ERROR:src.agents.search:DuckDuckGo search error: 200, message='Attempt to decode JSON with unexpected mimetype: application/x-javascript', url='https://api.duckduckgo.com/?q=AI+automation+trends+2024&format=json&no_html=1&skip_disambig=1'
INFO:     127.0.0.1:50242 - "POST /search HTTP/1.1" 200 OK
WARNING:src.core.ai_provider:All AI providers failed, using fallback response
ERROR:src.agents.conversational:Chat failed: VectorStore.store_conversation() missing 1 required positional argument: 'conversation_data'
Traceback (most recent call last):
  File "/workspace/src/agents/conversational.py", line 172, in chat
    content=response["content"],
      ^^^^^^^^^^^^^^^^^^^^^^^^^^
TypeError: VectorStore.store_conversation() missing 1 required positional argument: 'conversation_data'
INFO:     127.0.0.1:52880 - "POST /chat HTTP/1.1" 200 OK
INFO:     127.0.0.1:57260 - "GET /health HTTP/1.1" 200 OK
ERROR:src.agents.search:DuckDuckGo search error: 200, message='Attempt to decode JSON with unexpected mimetype: application/x-javascript', url='https://api.duckduckgo.com/?q=AI+automation+trends+2024&format=json&no_html=1&skip_disambig=1'
INFO:     127.0.0.1:57270 - "POST /search HTTP/1.1" 200 OK
WARNING:src.core.ai_provider:All AI providers failed, using fallback response
ERROR:src.agents.conversational:Chat failed: VectorStore.store_conversation() missing 1 required positional argument: 'conversation_data'
Traceback (most recent call last):
  File "/workspace/src/agents/conversational.py", line 172, in chat
    content=response["content"],
      ^^^^^^^^^^^^^^^^^^^^^^^^^^
TypeError: VectorStore.store_conversation() missing 1 required positional argument: 'conversation_data'
INFO:     127.0.0.1:57286 - "POST /chat HTTP/1.1" 200 OK
WARNING:src.core.ai_provider:All AI providers failed, using fallback response
ERROR:src.agents.conversational:Chat failed: VectorStore.store_conversation() missing 1 required positional argument: 'conversation_data'
Traceback (most recent call last):
  File "/workspace/src/agents/conversational.py", line 172, in chat
    content=response["content"],
      ^^^^^^^^^^^^^^^^^^^^^^^^^^
TypeError: VectorStore.store_conversation() missing 1 required positional argument: 'conversation_data'
INFO:     127.0.0.1:52532 - "POST /chat HTTP/1.1" 200 OK
WARNING:src.core.ai_provider:All AI providers failed, using fallback response
ERROR:src.agents.conversational:Chat failed: VectorStore.store_conversation() missing 1 required positional argument: 'conversation_data'
Traceback (most recent call last):
  File "/workspace/src/agents/conversational.py", line 172, in chat
    content=response["content"],
      ^^^^^^^^^^^^^^^^^^^^^^^^^^
TypeError: VectorStore.store_conversation() missing 1 required positional argument: 'conversation_data'
INFO:     127.0.0.1:37536 - "POST /chat HTTP/1.1" 200 OK
WARNING:src.core.ai_provider:All AI providers failed, using fallback response
ERROR:src.agents.conversational:Chat failed: VectorStore.store_conversation() missing 1 required positional argument: 'conversation_data'
Traceback (most recent call last):
  File "/workspace/src/agents/conversational.py", line 172, in chat
    content=response["content"],
      ^^^^^^^^^^^^^^^^^^^^^^^^^^
TypeError: VectorStore.store_conversation() missing 1 required positional argument: 'conversation_data'
INFO:     127.0.0.1:55278 - "POST /chat HTTP/1.1" 200 OK
WARNING:src.core.ai_provider:All AI providers failed, using fallback response
ERROR:src.agents.conversational:Chat failed: VectorStore.store_conversation() missing 1 required positional argument: 'conversation_data'
Traceback (most recent call last):
  File "/workspace/src/agents/conversational.py", line 172, in chat
    content=response["content"],
      ^^^^^^^^^^^^^^^^^^^^^^^^^^
TypeError: VectorStore.store_conversation() missing 1 required positional argument: 'conversation_data'
INFO:     127.0.0.1:55152 - "POST /chat HTTP/1.1" 200 OK
WARNING:src.core.ai_provider:All AI providers failed, using fallback response
ERROR:src.agents.conversational:Chat failed: VectorStore.store_conversation() missing 1 required positional argument: 'conversation_data'
Traceback (most recent call last):
  File "/workspace/src/agents/conversational.py", line 172, in chat
    content=response if isinstance(response, str) else response.get("content", str(response)),
      ^^^^^^^^^^^^^^^^^^^^^^^^^^^^^^^^^^^^^^^^^^^^^^^^^^
TypeError: VectorStore.store_conversation() missing 1 required positional argument: 'conversation_data'
INFO:     127.0.0.1:49702 - "POST /chat HTTP/1.1" 200 OK
WARNING:src.core.ai_provider:All AI providers failed, using fallback response
ERROR:src.agents.conversational:Chat failed: VectorStore.store_conversation() missing 1 required positional argument: 'conversation_data'
Traceback (most recent call last):
  File "/workspace/src/agents/conversational.py", line 172, in chat
    content=response if isinstance(response, str) else response.get("content", str(response)),
      ^^^^^^^^^^^^^^^^^^^^^^^^^^^^^^^^^^^^^^^^^^^^^^^^^^
TypeError: VectorStore.store_conversation() missing 1 required positional argument: 'conversation_data'
INFO:     127.0.0.1:52686 - "POST /chat HTTP/1.1" 200 OK
WARNING:src.core.ai_provider:All AI providers failed, using fallback response
ERROR:src.agents.conversational:Chat failed: VectorStore.store_conversation() missing 1 required positional argument: 'conversation_data'
Traceback (most recent call last):
  File "/workspace/src/agents/conversational.py", line 172, in chat
    content=response if isinstance(response, str) else response.get("content", str(response)),
      ^^^^^^^^^^^^^^^^^^^^^^^^^^^^^^^^^^^^^^^^^^^^^^^^^^
TypeError: VectorStore.store_conversation() missing 1 required positional argument: 'conversation_data'
INFO:     127.0.0.1:58494 - "POST /chat HTTP/1.1" 200 OK
WARNING:src.core.ai_provider:All AI providers failed, using fallback response
ERROR:src.agents.conversational:Chat failed: VectorStore.store_conversation() missing 1 required positional argument: 'conversation_data'
Traceback (most recent call last):
  File "/workspace/src/agents/conversational.py", line 172, in chat
    content=response if isinstance(response, str) else response.get("content", str(response)),
      ^^^^^^^^^^^^^^^^^^^^^^^^^^^^^^^^^^^^^^^^^^^^^^^^^^
TypeError: VectorStore.store_conversation() missing 1 required positional argument: 'conversation_data'
INFO:     127.0.0.1:50176 - "POST /chat HTTP/1.1" 200 OK
ERROR:src.agents.search:DuckDuckGo search error: 200, message='Attempt to decode JSON with unexpected mimetype: application/x-javascript', url='https://api.duckduckgo.com/?q=AI+automation+trends+2024&format=json&no_html=1&skip_disambig=1'
INFO:     127.0.0.1:50622 - "POST /search HTTP/1.1" 200 OK
WARNING:root:Agent execution failed, using fallback: 'ExecutionAgent' object has no attribute 'execute_automation'
INFO:     127.0.0.1:40972 - "POST /automation/execute HTTP/1.1" 200 OK
INFO:     127.0.0.1:47168 - "POST /export HTTP/1.1" 200 OK
WARNING:src.core.ai_provider:All AI providers failed, using fallback response
ERROR:src.agents.conversational:Chat failed: VectorStore.store_conversation() missing 1 required positional argument: 'conversation_data'
Traceback (most recent call last):
  File "/workspace/src/agents/conversational.py", line 172, in chat
    content=response if isinstance(response, str) else response.get("content", str(response)),
      ^^^^^^^^^^^^^^^^^^^^^^^^^^^^^^^^^^^^^^^^^^^^^^^^^^
TypeError: VectorStore.store_conversation() missing 1 required positional argument: 'conversation_data'
INFO:     127.0.0.1:46472 - "POST /chat HTTP/1.1" 200 OK
WARNING:src.core.ai_provider:All AI providers failed, using fallback response
ERROR:src.agents.conversational:Chat failed: VectorStore.store_conversation() missing 1 required positional argument: 'conversation_data'
Traceback (most recent call last):
  File "/workspace/src/agents/conversational.py", line 172, in chat
    content=response if isinstance(response, str) else response.get("content", str(response)),
      ^^^^^^^^^^^^^^^^^^^^^^^^^^^^^^^^^^^^^^^^^^^^^^^^^^
TypeError: VectorStore.store_conversation() missing 1 required positional argument: 'conversation_data'
INFO:     127.0.0.1:49138 - "POST /chat HTTP/1.1" 200 OK
WARNING:src.core.ai_provider:All AI providers failed, using fallback response
ERROR:src.agents.conversational:Chat failed: VectorStore.store_conversation() missing 1 required positional argument: 'conversation_data'
Traceback (most recent call last):
  File "/workspace/src/agents/conversational.py", line 172, in chat
    content=response if isinstance(response, str) else response.get("content", str(response)),
      ^^^^^^^^^^^^^^^^^^^^^^^^^^^^^^^^^^^^^^^^^^^^^^^^^^
TypeError: VectorStore.store_conversation() missing 1 required positional argument: 'conversation_data'
INFO:     127.0.0.1:39786 - "POST /chat HTTP/1.1" 200 OK
WARNING:src.core.ai_provider:All AI providers failed, using fallback response
ERROR:src.agents.conversational:Chat failed: VectorStore.store_conversation() missing 1 required positional argument: 'conversation_data'
Traceback (most recent call last):
  File "/workspace/src/agents/conversational.py", line 172, in chat
    content=response if isinstance(response, str) else response.get("content", str(response)),
      ^^^^^^^^^^^^^^^^^^^^^^^^^^^^^^^^^^^^^^^^^^^^^^^^^^
TypeError: VectorStore.store_conversation() missing 1 required positional argument: 'conversation_data'
INFO:     127.0.0.1:40340 - "POST /chat HTTP/1.1" 200 OK
WARNING:src.core.ai_provider:All AI providers failed, using fallback response
ERROR:src.agents.conversational:Chat failed: VectorStore.store_conversation() missing 1 required positional argument: 'conversation_data'
Traceback (most recent call last):
  File "/workspace/src/agents/conversational.py", line 172, in chat
    # Check if this is a handoff request
TypeError: VectorStore.store_conversation() missing 1 required positional argument: 'conversation_data'
INFO:     127.0.0.1:54354 - "POST /chat HTTP/1.1" 200 OK
WARNING:src.core.ai_provider:All AI providers failed, using fallback response
ERROR:src.agents.conversational:Chat failed: VectorStore.store_conversation() missing 1 required positional argument: 'conversation_data'
Traceback (most recent call last):
  File "/workspace/src/agents/conversational.py", line 172, in chat
    # Check if this is a handoff request
TypeError: VectorStore.store_conversation() missing 1 required positional argument: 'conversation_data'
INFO:     127.0.0.1:42170 - "POST /chat HTTP/1.1" 200 OK
WARNING:src.core.ai_provider:All AI providers failed, using fallback response
ERROR:src.agents.conversational:Chat failed: VectorStore.store_conversation() missing 1 required positional argument: 'conversation_data'
Traceback (most recent call last):
  File "/workspace/src/agents/conversational.py", line 172, in chat
    # Check if this is a handoff request
TypeError: VectorStore.store_conversation() missing 1 required positional argument: 'conversation_data'
INFO:     127.0.0.1:38968 - "POST /chat HTTP/1.1" 200 OK
WARNING:src.core.ai_provider:All AI providers failed, using fallback response
ERROR:src.agents.conversational:Chat failed: VectorStore.store_conversation() missing 1 required positional argument: 'conversation_data'
Traceback (most recent call last):
  File "/workspace/src/agents/conversational.py", line 172, in chat
    # Check if this is a handoff request
TypeError: VectorStore.store_conversation() missing 1 required positional argument: 'conversation_data'
INFO:     127.0.0.1:36356 - "POST /chat HTTP/1.1" 200 OK
WARNING:src.core.ai_provider:All AI providers failed, using fallback response
ERROR:src.agents.conversational:Chat failed: VectorStore.store_conversation() missing 1 required positional argument: 'conversation_data'
Traceback (most recent call last):
  File "/workspace/src/agents/conversational.py", line 172, in chat
TypeError: VectorStore.store_conversation() missing 1 required positional argument: 'conversation_data'
INFO:     127.0.0.1:32824 - "POST /chat HTTP/1.1" 200 OK
WARNING:src.core.ai_provider:All AI providers failed, using fallback response
ERROR:src.agents.conversational:Chat failed: VectorStore.store_conversation() missing 1 required positional argument: 'conversation_data'
Traceback (most recent call last):
  File "/workspace/src/agents/conversational.py", line 172, in chat
TypeError: VectorStore.store_conversation() missing 1 required positional argument: 'conversation_data'
INFO:     127.0.0.1:34036 - "POST /chat HTTP/1.1" 200 OK
